log/output_50_2022_GRU_gpu2.log
wandb: Currently logged in as: pqy000 (pqythu). Use `wandb login --relogin` to force relogin
GPU device ID: 2
newdata/50_2022.npy
0
2024-09-07 11:35:12.701063: I tensorflow/core/platform/cpu_feature_guard.cc:193] This TensorFlow binary is optimized with oneAPI Deep Neural Network Library (oneDNN) to use the following CPU instructions in performance-critical operations:  AVX2 FMA
To enable them in other operations, rebuild TensorFlow with the appropriate compiler flags.
2024-09-07 11:35:13.585204: W tensorflow/compiler/xla/stream_executor/platform/default/dso_loader.cc:64] Could not load dynamic library 'libnvinfer.so.7'; dlerror: libnvinfer.so.7: cannot open shared object file: No such file or directory; LD_LIBRARY_PATH: /opt/cudnn/lib64:/usr/local/cuda/lib64
2024-09-07 11:35:13.585309: W tensorflow/compiler/xla/stream_executor/platform/default/dso_loader.cc:64] Could not load dynamic library 'libnvinfer_plugin.so.7'; dlerror: libnvinfer_plugin.so.7: cannot open shared object file: No such file or directory; LD_LIBRARY_PATH: /opt/cudnn/lib64:/usr/local/cuda/lib64
2024-09-07 11:35:13.585322: W tensorflow/compiler/tf2tensorrt/utils/py_utils.cc:38] TF-TRT Warning: Cannot dlopen some TensorRT libraries. If you would like to use Nvidia GPU with TensorRT, please make sure the missing libraries mentioned above are installed properly.
wandb: wandb version 0.17.9 is available!  To upgrade, please run:
wandb:  $ pip install wandb --upgrade
wandb: Tracking run with wandb version 0.12.17
wandb: Run data is saved locally in /home/qingyi/GPU20/DeepLOB/wandb/run-20240907_113510-t4y5ldm7
wandb: Run `wandb offline` to turn off syncing.
wandb: Syncing run GRU
wandb: ⭐️ View project at https://wandb.ai/pqythu/futures50
wandb: 🚀 View run at https://wandb.ai/pqythu/futures50/runs/t4y5ldm7
Model(
  (rnn): GRU(10, 64, batch_first=True)
  (fc): Linear(in_features=64, out_features=5, bias=True)
)
number of parameters: 14917
Training start
epoch  1 | time used:  0.97s | train_loss 1.491 | valid loss 1.535 | valid acc 0.296 | mae 2.076 | mse 6.951 | rmse 2.64 | r2 -1.63 | sharp 1.89
epoch  2 | time used:  0.16s | train_loss 1.500 | valid loss 1.537 | valid acc 0.296 | mae 2.076 | mse 6.951 | rmse 2.64 | r2 -1.63 | sharp 1.89
epoch  3 | time used:  0.20s | train_loss 1.525 | valid loss 1.536 | valid acc 0.296 | mae 2.076 | mse 6.951 | rmse 2.64 | r2 -1.63 | sharp 1.89
epoch  4 | time used:  0.13s | train_loss 1.507 | valid loss 1.478 | valid acc 0.323 | mae 1.924 | mse 6.341 | rmse 2.52 | r2 -1.40 | sharp 0.00
epoch  5 | time used:  0.13s | train_loss 1.509 | valid loss 1.478 | valid acc 0.323 | mae 1.924 | mse 6.341 | rmse 2.52 | r2 -1.40 | sharp 0.00
epoch  6 | time used:  0.15s | train_loss 1.494 | valid loss 1.478 | valid acc 0.323 | mae 1.924 | mse 6.341 | rmse 2.52 | r2 -1.40 | sharp 0.00
epoch  7 | time used:  0.14s | train_loss 1.514 | valid loss 1.537 | valid acc 0.296 | mae 2.076 | mse 6.951 | rmse 2.64 | r2 -1.63 | sharp 1.89
epoch  8 | time used:  0.14s | train_loss 1.502 | valid loss 1.479 | valid acc 0.323 | mae 1.924 | mse 6.341 | rmse 2.52 | r2 -1.40 | sharp 0.00
epoch  9 | time used:  0.17s | train_loss 1.491 | valid loss 1.537 | valid acc 0.296 | mae 2.076 | mse 6.951 | rmse 2.64 | r2 -1.63 | sharp 1.89
epoch 10 | time used:  0.14s | train_loss 1.519 | valid loss 1.478 | valid acc 0.323 | mae 1.924 | mse 6.341 | rmse 2.52 | r2 -1.40 | sharp 0.00
saving the model to ./save/2022_50/GRU/checkpoint10.pt
epoch 11 | time used:  0.14s | train_loss 1.489 | valid loss 1.535 | valid acc 0.296 | mae 2.076 | mse 6.951 | rmse 2.64 | r2 -1.63 | sharp 1.89
epoch 12 | time used:  0.15s | train_loss 1.500 | valid loss 1.478 | valid acc 0.323 | mae 1.924 | mse 6.341 | rmse 2.52 | r2 -1.40 | sharp 0.00
epoch 13 | time used:  0.15s | train_loss 1.530 | valid loss 1.478 | valid acc 0.323 | mae 1.924 | mse 6.341 | rmse 2.52 | r2 -1.40 | sharp 0.00
epoch 14 | time used:  0.24s | train_loss 1.494 | valid loss 1.478 | valid acc 0.323 | mae 1.924 | mse 6.341 | rmse 2.52 | r2 -1.40 | sharp 0.00
epoch 15 | time used:  0.13s | train_loss 1.515 | valid loss 1.478 | valid acc 0.323 | mae 1.924 | mse 6.341 | rmse 2.52 | r2 -1.40 | sharp 0.00
epoch 16 | time used:  0.20s | train_loss 1.494 | valid loss 1.537 | valid acc 0.296 | mae 2.076 | mse 6.951 | rmse 2.64 | r2 -1.63 | sharp 1.89
epoch 17 | time used:  0.15s | train_loss 1.521 | valid loss 1.537 | valid acc 0.296 | mae 2.076 | mse 6.951 | rmse 2.64 | r2 -1.63 | sharp 1.89
epoch 18 | time used:  0.18s | train_loss 1.511 | valid loss 1.537 | valid acc 0.296 | mae 2.076 | mse 6.951 | rmse 2.64 | r2 -1.63 | sharp 1.89
epoch 19 | time used:  0.17s | train_loss 1.521 | valid loss 1.478 | valid acc 0.323 | mae 1.924 | mse 6.341 | rmse 2.52 | r2 -1.40 | sharp 0.00
epoch 20 | time used:  0.20s | train_loss 1.491 | valid loss 1.478 | valid acc 0.323 | mae 1.924 | mse 6.341 | rmse 2.52 | r2 -1.40 | sharp 0.00
saving the model to ./save/2022_50/GRU/checkpoint20.pt
epoch 21 | time used:  0.16s | train_loss 1.496 | valid loss 1.478 | valid acc 0.323 | mae 1.924 | mse 6.341 | rmse 2.52 | r2 -1.40 | sharp 0.00
epoch 22 | time used:  0.17s | train_loss 1.502 | valid loss 1.537 | valid acc 0.296 | mae 2.076 | mse 6.951 | rmse 2.64 | r2 -1.63 | sharp 1.89
epoch 23 | time used:  0.18s | train_loss 1.521 | valid loss 1.536 | valid acc 0.296 | mae 2.076 | mse 6.951 | rmse 2.64 | r2 -1.63 | sharp 1.89
epoch 24 | time used:  0.19s | train_loss 1.508 | valid loss 1.478 | valid acc 0.323 | mae 1.924 | mse 6.341 | rmse 2.52 | r2 -1.40 | sharp 0.00
epoch 25 | time used:  0.16s | train_loss 1.530 | valid loss 1.537 | valid acc 0.296 | mae 2.076 | mse 6.951 | rmse 2.64 | r2 -1.63 | sharp 1.89
epoch 26 | time used:  0.18s | train_loss 1.523 | valid loss 1.478 | valid acc 0.323 | mae 1.924 | mse 6.341 | rmse 2.52 | r2 -1.40 | sharp 0.00
epoch 27 | time used:  0.15s | train_loss 1.495 | valid loss 1.478 | valid acc 0.323 | mae 1.924 | mse 6.341 | rmse 2.52 | r2 -1.40 | sharp 0.00
epoch 28 | time used:  0.23s | train_loss 1.494 | valid loss 1.478 | valid acc 0.323 | mae 1.924 | mse 6.341 | rmse 2.52 | r2 -1.40 | sharp 0.00
epoch 29 | time used:  0.15s | train_loss 1.498 | valid loss 1.478 | valid acc 0.323 | mae 1.924 | mse 6.341 | rmse 2.52 | r2 -1.40 | sharp 0.00
epoch 30 | time used:  0.16s | train_loss 1.514 | valid loss 1.537 | valid acc 0.296 | mae 2.076 | mse 6.951 | rmse 2.64 | r2 -1.63 | sharp 1.89
saving the model to ./save/2022_50/GRU/checkpoint30.pt
epoch 31 | time used:  0.19s | train_loss 1.513 | valid loss 1.537 | valid acc 0.296 | mae 2.076 | mse 6.951 | rmse 2.64 | r2 -1.63 | sharp 1.89
epoch 32 | time used:  0.21s | train_loss 1.519 | valid loss 1.537 | valid acc 0.296 | mae 2.076 | mse 6.951 | rmse 2.64 | r2 -1.63 | sharp 1.89
epoch 33 | time used:  0.17s | train_loss 1.507 | valid loss 1.479 | valid acc 0.323 | mae 1.924 | mse 6.341 | rmse 2.52 | r2 -1.40 | sharp 0.00
epoch 34 | time used:  0.20s | train_loss 1.511 | valid loss 1.673 | valid acc 0.210 | mae 1.409 | mse 2.646 | rmse 1.63 | r2 -0.00 | sharp 1.89
epoch 35 | time used:  0.20s | train_loss 1.497 | valid loss 1.478 | valid acc 0.323 | mae 1.924 | mse 6.341 | rmse 2.52 | r2 -1.40 | sharp 0.00
epoch 36 | time used:  0.27s | train_loss 1.525 | valid loss 1.478 | valid acc 0.323 | mae 1.924 | mse 6.341 | rmse 2.52 | r2 -1.40 | sharp 0.00
epoch 37 | time used:  0.18s | train_loss 1.496 | valid loss 1.792 | valid acc 0.210 | mae 1.409 | mse 2.646 | rmse 1.63 | r2 -0.00 | sharp 1.89
epoch 38 | time used:  0.17s | train_loss 1.512 | valid loss 1.478 | valid acc 0.323 | mae 1.924 | mse 6.341 | rmse 2.52 | r2 -1.40 | sharp 0.00
epoch 39 | time used:  0.18s | train_loss 1.531 | valid loss 1.537 | valid acc 0.296 | mae 2.076 | mse 6.951 | rmse 2.64 | r2 -1.63 | sharp 1.89
epoch 40 | time used:  0.16s | train_loss 1.506 | valid loss 1.478 | valid acc 0.323 | mae 1.924 | mse 6.341 | rmse 2.52 | r2 -1.40 | sharp 0.00
saving the model to ./save/2022_50/GRU/checkpoint40.pt
